#VRML_SIM R2020b utf8
WorldInfo {
  coordinateSystem "NUE"
}
Viewpoint {
  orientation -0.4752223492235546 -0.6990527231980543 -0.5343117151886435 2.040440682805006
  position -0.6295569901453358 2.7076778956957703 -0.03634673524724513
}
TexturedBackground {
  texture "factory"
}
TexturedBackgroundLight {
}
DEF RedCylinder Solid {
  translation 0.508 0.14925005297109933 0.508
  rotation -0.4436644451670948 0.8924131796216109 0.08222272758927664 -9.307289899444879e-16
  children [
    Shape {
      appearance PBRAppearance {
        baseColor 1 0 0
        roughness 1
        metalness 0
      }
      geometry Cylinder {
        height 0.381
        radius 0.08
      }
    }
  ]
  name "solid(1)"
  boundingObject DEF landmark Shape {
    appearance PBRAppearance {
      baseColor 0 1 1
      roughness 1
      metalness 0
    }
    geometry Cylinder {
      height 0.3
      radius 0.045
    }
  }
  physics DEF landmarkPH Physics {
  }
  locked TRUE
  recognitionColors [
    1 1 0
  ]
}
DEF YellowCylinder Solid {
  translation 0.508 0.14925005297109933 -0.508
  rotation -0.433103795997105 0.8845940937974257 0.17295777262560225 -9.147712488515627e-16
  children [
    Shape {
      appearance PBRAppearance {
        baseColor 1 1 0
        roughness 1
        metalness 0
      }
      geometry Cylinder {
        height 0.381
        radius 0.08
      }
    }
  ]
  name "solid(4)"
  boundingObject DEF landmark Shape {
    appearance PBRAppearance {
      baseColor 0 1 1
      roughness 1
      metalness 0
    }
    geometry Cylinder {
      height 0.3
      radius 0.045
    }
  }
  physics DEF landmarkPH Physics {
  }
  locked TRUE
  recognitionColors [
    1 1 0
  ]
}
DEF GreenCylinder Solid {
  translation -0.508 0.14925005297109933 -0.508
  rotation -0.40569502728575974 0.8977539787803817 0.17160809543725108 -8.02348892126221e-16
  children [
    Shape {
      appearance PBRAppearance {
        baseColor 0 1 0
        roughness 1
        metalness 0
      }
      geometry Cylinder {
        height 0.381
        radius 0.08
      }
    }
  ]
  name "solid(3)"
  boundingObject DEF landmark Shape {
    appearance PBRAppearance {
      baseColor 0 1 1
      roughness 1
      metalness 0
    }
    geometry Cylinder {
      height 0.3
      radius 0.045
    }
  }
  physics DEF landmarkPH Physics {
  }
  locked TRUE
  recognitionColors [
    1 1 0
  ]
}
DEF BlueCylinder Solid {
  translation -0.508 0.14925005297109933 0.508
  rotation -0.3756844276619212 0.9116379008733119 0.16666597884282253 -9.35757902786734e-16
  children [
    Shape {
      appearance PBRAppearance {
        baseColor 0 0 1
        roughness 1
        metalness 0
      }
      geometry Cylinder {
        height 0.381
        radius 0.08
      }
    }
  ]
  name "solid(5)"
  boundingObject DEF landmark Shape {
    appearance PBRAppearance {
      baseColor 0 1 1
      roughness 1
      metalness 0
    }
    geometry Cylinder {
      height 0.3
      radius 0.045
    }
  }
  physics DEF landmarkPH Physics {
  }
  locked TRUE
  recognitionColors [
    1 1 0
  ]
}
DEF area RectangleArena {
  floorSize 1.016 1.016
  floorTileSize 0.508 0.508
  wallAppearance BrushedAluminium {
    colorOverride 0 0 0
  }
}
DEF epuck E-puck {
  hidden position_0_0 7.543342321696883e-09
  hidden position_0_1 -2.5490206716284983e-08
  hidden rotation_2 1 0 0 2.9802322387695313e-08
  translation 0.36557161401530097 -0.00010131135517090634 0.39206611038903316
  rotation -0.04240595304833459 -0.9990997350541221 0.0012060517590162104 0.0037932209207047246
  controller "<extern>"
  supervisor TRUE
  camera_width 50
  turretSlot [
    InertialUnit {
      rotation 0 1 0 3.14
    }
    DEF righthinge HingeJoint {
      jointParameters HingeJointParameters {
        position 4.152668962133874e-08
        axis -1 0 0
        anchor 0 0.025 0
      }
      device [
        RotationalMotor {
          name "right wheel motor"
          consumptionFactor 70
          controlPID 8 2 0.5
        }
        PositionSensor {
          name "right wheel sensor"
        }
      ]
      endPoint Solid {
        translation 0.04500995778380096 0.02501338075785909 -2.4671930407728815e-05
        rotation 0.9999993203500066 0.0010052733953939028 -0.0005905293603570323 4.636837080528007
        children [
          DEF WHEEL Transform {
            translation -0.007 0.01 -0.05
            rotation 0 0 1 1.57
            children [
              Shape {
                appearance PBRAppearance {
                  baseColor 0 0 0
                  transparency 1
                  roughness 1
                  metalness 0
                }
                geometry Cylinder {
                  height 0.01
                  radius 0.02
                }
              }
            ]
            rotationStep 0.25
          }
        ]
        name "right wheel(1)"
        boundingObject USE WHEEL
        physics DEF PHYSICS_WHEEL Physics {
          density -1
          mass 0.05
        }
        rotationStep 0.25
      }
    }
    DEF lefthinge HingeJoint {
      jointParameters HingeJointParameters {
        position 2.9898274185666315e-08
        axis -1 0 0
        anchor 0 0.025 0
      }
      device [
        RotationalMotor {
          name "left wheel motor"
          consumptionFactor 70
          controlPID 8 0 0
        }
        PositionSensor {
          name "left wheel sensor"
        }
      ]
      endPoint Solid {
        translation -0.04501012942703836 0.0249776719759117 -4.573397549446566e-05
        rotation -0.9999982113395917 0.00047275264888793286 -0.0018313444653098464 1.2425810501871795
        children [
          DEF WHEEL Transform {
            translation 0.007 0 -0.05
            rotation 0 0 1 1.57
            children [
              Shape {
                appearance PBRAppearance {
                  baseColor 0.1 0.1 0.1
                  transparency 1
                  roughness 1
                  metalness 0
                }
                geometry Cylinder {
                  height 0.01
                  radius 0.02
                }
              }
            ]
            rotationStep 0.25
          }
        ]
        name "left wheel(1)"
        boundingObject USE WHEEL
        physics DEF PHYSICS_WHEEL Physics {
          density -1
          mass 0.05
        }
      }
    }
    DEF front_ds DistanceSensor {
      translation 0 0 -0.045
      rotation 0 1 0 1.5708
      name "front_ds"
      recognitionColors [
        0 0 0
      ]
      lookupTable [
        0 0 0
        1.27 1.27 0
      ]
    }
    DEF right_ds DistanceSensor {
      translation 0.035 -0.01 -0.01
      name "right_ds"
      lookupTable [
        0 0 0
        1.27 1.27 0
      ]
    }
    DEF left_ds DistanceSensor {
      translation -0.035 -0.01 -0.01
      rotation 0 1 0 3.14159
      name "left_ds"
      lookupTable [
        0 0 0
        1.27 1.27 0
      ]
    }
    Camera {
      translation 0 -0.01 -0.045
      name "camera1"
      recognitionColors [
        1 1 0
      ]
      fieldOfView 1.57
      width 80
      height 80
      recognition Recognition {
      }
    }
  ]
}
